Workbook

Sheet Assets
A1: ID | B1: Category | C1: Item | D1: Qty | E1: Spec / Dimensions | F1: Format | G1: Milestone | H1: Priority | I1: Status | J1: Notes
A2: T-001 | B2: Tiles | C2: 萬 suit faces 1–9 | D2: 9 | E2: 96×128 pt design base; engraved glyph; export @1x/2x/3x atlas | F2: PNG atlas (SVG master) | G2: M3 | H2: P0 | I2: Not started | J2: Traditional red/black glyphs
A3: T-002 | B3: Tiles | C3: 筒 suit faces 1–9 | D3: 9 | E3: 96×128 pt; @1x/2x/3x | F3: PNG atlas (SVG master) | G3: M3 | H3: P0 | I3: Not started | J3: Blue/black
A4: T-003 | B4: Tiles | C4: 索 suit faces 1–9 | D4: 9 | E4: 96×128 pt; @1x/2x/3x | F4: PNG atlas (SVG master) | G4: M3 | H4: P0 | I4: Not started | J4: Green; 1索 bird
A5: T-004 | B5: Tiles | C5: Wind faces 東南西北 | D5: 4 | E5: 96×128 pt; @1x/2x/3x | F5: PNG atlas (SVG master) | G5: M3 | H5: P0 | I5: Not started
A6: T-005 | B6: Tiles | C6: Dragon faces 中發白 | D6: 3 | E6: 96×128 pt; @1x/2x/3x | F6: PNG atlas (SVG master) | G6: M3 | H6: P0 | I6: Not started | J6: 白 = blue frame
A7: T-006 | B7: Tiles | C7: Flower faces 春夏秋冬梅蘭菊竹 | D7: 8 | E7: 96×128 pt; ornate but distinct silhouettes | F7: PNG atlas (SVG master) | G7: M3 | H7: P0 | I7: Not started
A8: T-007 | B8: Tiles | C8: 百搭 joker face | D8: 1 | E8: 96×128 pt; gold 百搭 glyph + jade glow; must read at 40×54 river size | F8: PNG atlas (SVG master) | G8: M4 | H8: P0 | I8: Not started | J8: GDD 01 §4
A9: T-008 | B9: Tiles | C9: Tile back | D9: 1 | E9: 96×128 pt; 麻雀綠 lattice | F9: PNG atlas | G9: M3 | H9: P0 | I9: Not started
A10: T-009 | B10: Tiles | C10: Tile side/edge chrome | D10: 1 | E10: 9-patch or per-size sprite | F10: PNG | G10: M3 | H10: P1 | I10: Not started | J10: 3D-ish depth
A11: T-010 | B11: Tiles | C11: Face-down wall pair sprite | D11: 1 | E11: stacked 2-tile unit for wall render | F11: PNG atlas | G11: M3 | H11: P0 | I11: Not started
A12: E-001 | B12: Table & props | C12: Table frame + green inlay | D12: 1 | E12: per-aspect bg or 9-patch; rosewood #5C3A21 / inlay #2E5E4E | F12: PNG | G12: M3 | H12: P0 | I12: Not started
A13: E-002 | B13: Table & props | C13: Room backdrop w/ neon dressing | D13: 3 | E13: layered PNGs, parallax-lite; low contrast | F13: PNG | G13: M5 | H13: P2 | I13: Not started | J13: Non-play-area dressing
A14: E-003 | B14: Table & props | C14: Center hub panel (拉牌盒 style) | D14: 1 | E14: square panel; holds 圈風/局數/牌數/骰 | F14: PNG + widget | G14: M3 | H14: P0 | I14: Not started
A15: E-004 | B15: Table & props | C15: 莊 dealer coin | D15: 1 | E15: brass style, 64×64 | F15: PNG | G15: M3 | H15: P0 | I15: Not started
A16: E-005 | B16: Table & props | C16: 拉莊 chip stack numerals 1–9 | D16: 9 | E16: red chips w/ 拉N numeral | F16: PNG atlas | G16: M3 | H16: P1 | I16: Not started
A17: E-006 | B17: Table & props | C17: Dice faces + tumble animation | D17: 1 | E17: faces 1–6 + tumble sprite sheet ~600ms | F17: PNG sheet | G17: M3 | H17: P0 | I17: Not started | J17: Used by 開門/執位/換牌
A18: E-007 | B18: Table & props | C18: Seat wind chips 東南西北 | D18: 4 | E18: small chips beside avatars | F18: PNG atlas | G18: M3 | H18: P0 | I18: Not started
A19: E-008 | B19: Table & props | C19: Seat frame / name plate | D19: 1 | E19: holds avatar+name+badges | F19: PNG 9-patch | G19: M3 | H19: P0 | I19: Not started
A20: E-009 | B20: Table & props | C20: Status badges (AI robot, wifi-off, host crown) | D20: 3 | E20: 24–32 px | F20: PNG atlas | G20: M3 | H20: P1 | I20: Not started
A21: E-010 | B21: Table & props | C21: Room-code card + QR frame | D21: 1 | E21: share screen hero card | F21: PNG + widget | G21: M5 | H21: P1 | I21: Not started
A22: E-011 | B22: Table & props | C22: 叮 red corner tag | D22: 1 | E22: river-tile overlay tag | F22: PNG | G22: M3 | H22: P0 | I22: Not started
A23: A-001 | B23: Avatars | C23: Player avatar set (茶餐廳 theme) | D23: 14 | E23: 128×128 round; 奶茶/菠蘿包/蛋撻/燒賣/貓店長/雀友… | F23: PNG atlas | G23: M5 | H23: P1 | I23: Not started | J23: 12–16 target
A24: A-002 | B24: Avatars | C24: AI mascot avatars | D24: 4 | E24: robot-ified variants of A-001 style | F24: PNG atlas | G24: M4 | H24: P1 | I24: Not started
A25: U-001 | B25: UI kit | C25: Action pill buttons 食/碰/槓/上/叮/過 | D25: 18 | E25: 6 colorways × 3 states (normal/pressed/disabled); ≥64 px tall | F25: PNG 9-patch/widget | G25: M3 | H25: P0 | I25: Not started | J25: Color coding per GDD 01 §8
A26: U-002 | B26: UI kit | C26: Menu buttons primary/secondary | D26: 6 | E26: pill, neon border active | F26: widget theme | G26: M3 | H26: P0 | I26: Not started | J26: Mostly Flutter theming
A27: U-003 | B27: UI kit | C27: Form controls (toggle/stepper/slider/radio-card) | D27: 4 | E27: editor + wizard styling | F27: widget theme | G27: M4 | H27: P0 | I27: Not started
A28: U-004 | B28: UI kit | C28: Countdown ring | D28: 1 | E28: draining ring; shader or sprite sheet | F28: shader/sheet | G28: M3 | H28: P0 | I28: Not started | J28: Claim & turn timers
A29: U-005 | B29: UI kit | C29: Dialog/sheet frames | D29: 2 | E29: dark card + gold rule line | F29: PNG 9-patch | G29: M3 | H29: P0 | I29: Not started
A30: U-006 | B30: UI kit | C30: List cells (editor row, 圖鑑 card) | D30: 2 | E30: widget styling | F30: widget theme | G30: M4 | H30: P0 | I30: Not started
A31: U-007 | B31: UI kit | C31: Rules summary chip | D31: 1 | E31: lobby/table diff-vs-official chip | F31: widget | G31: M4 | H31: P1 | I31: Not started
A32: U-008 | B32: UI kit | C32: Ledger strip elements (chain link/broken/口 dot) | D32: 3 | E32: compact strip art | F32: PNG atlas | G32: M3 | H32: P1 | I32: Not started | J32: 拉/踢半 UI
A33: U-009 | B33: UI kit | C33: Line icon set | D33: 30 | E33: 2 px stroke, rounded; settings/share/sound/help/edit/save/replay/QR/exit/kick/fairness… | F33: SVG→font/atlas | G33: M3 | H33: P1 | I33: Not started
A34: U-010 | B34: UI kit | C34: App fonts (Noto Sans TC + display face) | D34: 2 | E34: OFL check for display face; tnum digits | F34: TTF/OTF | G34: M3 | H34: P0 | I34: Not started | J34: GDD 01 §3; license gate
A35: V-001 | B35: VFX | C35: Deal sweep trail | D35: 1 | E35: 40 ms/tile stagger | F35: engine FX | G35: M3 | H35: P1 | I35: Not started
A36: V-002 | B36: VFX | C36: Claim word flash cards 上/碰/槓/食/自摸/搶槓/雙響 | D36: 7 | E36: display-type card + neon burst | F36: PNG + FX | G36: M3 | H36: P0 | I36: Not started
A37: V-003 | B37: VFX | C37: 叮 stamp effect | D37: 1 | E37: red stamp thunk ≤400 ms | F37: sprite/FX | G37: M3 | H37: P0 | I37: Not started
A38: V-004 | B38: VFX | C38: Win fan-out glow + 番 row cascade | D38: 1 | E38: win overlay sequence | F38: engine FX | G38: M3 | H38: P0 | I38: Not started
A39: V-005 | B39: VFX | C39: Gold count-up particles + brass tick sync | D39: 1 | E39: score总 count-up | F39: engine FX | G39: M3 | H39: P1 | I39: Not started
A40: V-006 | B40: VFX | C40: Confetti (big win) | D40: 1 | E40: ≥100番 tier | F40: engine FX | G40: M4 | H40: P2 | I40: Not started
...

Sheet Summary
A1: Asset Production Summary
A2: 《開枱》港式台牌 — asset tracker · basis: game-design-doc/09-ASSETS.md · 2026-07-07
A4: By category
A5: Category | B5: Line items | C5: Unit qty | D5: Done
A6: Tiles | B6: =COUNTIF(Assets!B2:B62,A6) -> 10 | C6: =SUMIF(Assets!B2:B62,A6,Assets!D2:D62) -> 46 | D6: =COUNTIFS(Assets!B2:B62,A6,Assets!I2:I62,"Done") -> 0
A7: Table & props | B7: =COUNTIF(Assets!B2:B62,A7) -> 11 | C7: =SUMIF(Assets!B2:B62,A7,Assets!D2:D62) -> 26 | D7: =COUNTIFS(Assets!B2:B62,A7,Assets!I2:I62,"Done") -> 0
A8: Avatars | B8: =COUNTIF(Assets!B2:B62,A8) -> 2 | C8: =SUMIF(Assets!B2:B62,A8,Assets!D2:D62) -> 18 | D8: =COUNTIFS(Assets!B2:B62,A8,Assets!I2:I62,"Done") -> 0
A9: UI kit | B9: =COUNTIF(Assets!B2:B62,A9) -> 10 | C9: =SUMIF(Assets!B2:B62,A9,Assets!D2:D62) -> 69 | D9: =COUNTIFS(Assets!B2:B62,A9,Assets!I2:I62,"Done") -> 0
A10: VFX | B10: =COUNTIF(Assets!B2:B62,A10) -> 11 | C10: =SUMIF(Assets!B2:B62,A10,Assets!D2:D62) -> 19 | D10: =COUNTIFS(Assets!B2:B62,A10,Assets!I2:I62,"Done") -> 0
A11: Audio | B11: =COUNTIF(Assets!B2:B62,A11) -> 5 | C11: =SUMIF(Assets!B2:B62,A11,Assets!D2:D62) -> 41 | D11: =COUNTIFS(Assets!B2:B62,A11,Assets!I2:I62,"Done") -> 0
A12: Data/content | B12: =COUNTIF(Assets!B2:B62,A12) -> 6 | C12: =SUMIF(Assets!B2:B62,A12,Assets!D2:D62) -> 166 | D12: =COUNTIFS(Assets!B2:B62,A12,Assets!I2:I62,"Done") -> 0
A13: Store | B13: =COUNTIF(Assets!B2:B62,A13) -> 6 | C13: =SUMIF(Assets!B2:B62,A13,Assets!D2:D62) -> 13 | D13: =COUNTIFS(Assets!B2:B62,A13,Assets!I2:I62,"Done") -> 0
A14: TOTAL | B14: =SUM(B6:B13) -> 61 | C14: =SUM(C6:C13) -> 398 | D14: =SUM(D6:D13) -> 0
A16: By priority
A17: Priority | B17: Line items
A18: P0 | B18: =COUNTIF(Assets!H2:H62,A18) -> 37
A19: P1 | B19: =COUNTIF(Assets!H2:H62,A19) -> 16
A20: P2 | B20: =COUNTIF(Assets!H2:H62,A20) -> 8
A22: By milestone
A23: Milestone | B23: Line items
A24: M1 | B24: =COUNTIF(Assets!G2:G62,A24) -> 1
A25: M3 | B25: =COUNTIF(Assets!G2:G62,A25) -> 34
A26: M4 | B26: =COUNTIF(Assets!G2:G62,A26) -> 9
A27: M4+ | B27: =COUNTIF(Assets!G2:G62,A27) -> 1
A28: M5 | B28: =COUNTIF(Assets!G2:G62,A28) -> 8
A29: M6 | B29: =COUNTIF(Assets!G2:G62,A29) -> 7
A30: M3–M5 | B30: =COUNTIF(Assets!G2:G62,A30) -> 1
